File: test.txt
Filename	cn-1-zif4-cl-mech-dsc
Instrument name	DSC2-01452 (129.217.217.186)
Operator	Christian Nelle
rundate	09.03.2023
Sample name	CN-1-ZIF4-Cl-MECH-DSC
proceduresegments	Equilibrate 50,00 °C; Ramp 10,00 °C/min to 350,00 °C; Ramp 10,00 °C/min to 100,00 °C; Ramp 10,00 °C/min to 350,00 °C; Ramp 10,00 °C/min to 100,00 °C
[File Parameters]
Run date	09.03.2023 16:45:57
Trios version	5.1.1.46572
Original File Name	C:\ProgramData\TA Instruments\TRIOS\Data\CN-1-ZIF4-Cl-MECH-DSC.tri
Current File Name	c:\users\chris\desktop\master henke\dsc\cn-1-zif4-cl-mech-dsc.tri
[Procedure]
Procedure Name	Nelle
Sample Name	CN-1-ZIF4-Cl-MECH-DSC
Sample Mass	12,3 mg
Pan Mass	0 mg
Pan Number	0
Reference Pan Number	0
Pan Type	Tzero Aluminum Hermetic
Comments	Chloro-Imidazol ZIF-4 Mixed Linker mechanosynthetisch
Project Name	Forschungspraktikum
Operator	Christian Nelle
Test	Custom
Unload Max Temperature	25
Unload Min Temperature	25
Load Max Temperature	25
Load Min Temperature	25
Stop on Gas Flow Error	Yes
[Signal List]
Signal #1	Time (min)
Signal #2	Temperature (°C)
Signal #3	Heat Flow (mW)
Signal #4	Delta T (µV)
Signal #5	Delta Tzero (µV)
Signal #6	Tzero Temperature (°C)
Signal #7	Cell Purge (mL/min)
Signal #8	Heater Temp (°C)
Signal #9	Power Delivered (W)
Signal #10	Reference Junction Temperature (°C)
Signal #11	Flange Temperature (°C)
Signal #12	Heat Flow Phase (rad)
Signal #13	Total Heat Capacity (J/°C)
[Configuration]
Company Name	TU Dortmund
Instrument Name	DSC2-01452
Instrument Type	DSC25
Serial Number	DSC2-01452
IP	129.217.217.186
Location of Instrument	Manufacturing Test
DisplayType	TianmaV2
Sample Interval 	0,1 s/pt
Selected Heat Flow	T1
Exotherm Direction	Down
Cell Serial	DRC2-03227
Lid Type	High Temperature
Cooler	Finned Air Cooler
Leave Cooler on at End of Sequence	On
Gas 2	Argon
Gas Selected	Channel 1
Flow Rate	50 mL/min
Secondary Purge	Off
Licensed Heat Flow	Heat Flow T1
Modulation Licensed	Yes
[Versions]
Common IDD Version	1
Cortex Version	VER 2.10.2.31
Driver	5.0.0.6
GDM Version	1.0.3.3
TouchscreenVersion	1.0.0.16145
FEP Version	1.2.1.21
FEP Bootloader	2.0.0.5
FCM Version	1.1.0.3
FCM Bootloader	2.0.0.5
[Experiment Logs]
Experiment Log Entry # 1	Air Cool is on.
Experiment Log Entry # 3	Equilibrate Segment 50 (C) Started
Experiment Log Entry # 5	Ramp Segment 10 C/min to 350 Started
Experiment Log Entry # 7	Ramp Segment 10 C/min to 100 Started
Experiment Log Entry # 9	Ramp Segment 10 C/min to 350 Started
Experiment Log Entry # 11	Ramp Segment 10 C/min to 100 Started
[Method Log]
Method Log Entry # 1	Equilibrate 50 °C
Method Log Entry # 2	(Ramp 430096) Ramp 10 °C/minute to 350 °C
Method Log Entry # 3	(Ramp 430097) Ramp 10 °C/minute to 100 °C
Method Log Entry # 4	(Ramp 430098) Ramp 10 °C/minute to 350 °C
Method Log Entry # 5	(Ramp 430099) Ramp 10 °C/minute to 100 °C
Cell Serial	DRC2-03227
[T1 Calibration]
Date Applied	25.06.2020 15:18:30
Description	From 55,000 °C to 700,120 °C at 10,000°C/min
Gas Type	Nitrogen
Pan Type	None
Source Files 1	C:\ProgramData\TA Instruments\TRIOS\Data\TA_Service\DSC25\Install_DSC_06_2020\Baseline calibration.tri
Slope	-0,001059477
Offset	2,508943
Initial Temperature	55
GUID	73373065-9eac-4ad8-b072-88be4d4ed3b7
[TZero Calibration]
(Not Applied)
[Temperature Calibration]
Date Applied	25.06.2020 18:19:27
Description	From 106,590 °C to 186,590 °C at 10,000°C/min
Gas Type	Nitrogen
Pan Type	Tzero Aluminum
Source Files 1	C:\ProgramData\TA Instruments\TRIOS\Data\TA_Service\DSC25\Install_DSC_06_2020\Indium(1).tri
Source Files 2	C:\ProgramData\TA Instruments\TRIOS\Data\TA_Service\DSC25\Install_DSC_06_2020\Tin.tri
Source Files 3	C:\ProgramData\TA Instruments\TRIOS\Data\TA_Service\DSC25\Install_DSC_06_2020\Lead.tri
Source Files 4	C:\ProgramData\TA Instruments\TRIOS\Data\TA_Service\DSC25\Install_DSC_06_2020\Zinc(1).tri
Measured 1	157,3877
Known 1	156,598
Measured 2	232,8055
Known 2	231,93
Measured 3	328,5554
Known 3	327,5
Measured 4	421,0261
Known 4	419,53
[Cell Constant Calibration]
Date Applied	25.06.2020 18:19:27
Description	From 106,590 °C to 186,590 °C at 10,000°C/min
Gas Type	Nitrogen
Pan Type	Tzero Aluminum
Source Files 1	C:\ProgramData\TA Instruments\TRIOS\Data\TA_Service\DSC25\Install_DSC_06_2020\Indium(1).tri
Source Files 2	C:\ProgramData\TA Instruments\TRIOS\Data\TA_Service\DSC25\Install_DSC_06_2020\Tin.tri
Source Files 3	C:\ProgramData\TA Instruments\TRIOS\Data\TA_Service\DSC25\Install_DSC_06_2020\Lead.tri
Source Files 4	C:\ProgramData\TA Instruments\TRIOS\Data\TA_Service\DSC25\Install_DSC_06_2020\Zinc(1).tri
T1 KCell	0,9970351
Onset Slope	-49,91871 mW/°C
[Direct Cp Calibration]
(Not Applied)
[Rev Cp Calibration]
Date Applied	15.02.2023 23:20:53
Description	From 60.003 °C to 398.222 °C at 2.000°C/min
Gas Type	Nitrogen
Pan Type	Tzero Aluminum Hermetic
Source Files 1	C:\ProgramData\TA Instruments\TRIOS\Data\Rev_Cp_Calibration_2Kmin_50_450C.tri
[step]
Ramp 10.00 °C/min to 350.000 °C
Time	Temperature	Heat Flow (Normalized)
min	°C	W/g
0,00	50,00	-0,037
0,02	50,01	-0,041
0,04	50,03	-0,044
0,06	50,08	-0,043
0,08	50,15	-0,040
0,10	50,25	-0,030
0,12	50,38	-0,020
0,14	50,52	-0,010
0,16	50,67	-0,001
0,18	50,82	0,009
0,20	50,99	0,018
0,22	51,15	0,027
0,24	51,33	0,035
0,26	51,51	0,042
0,28	51,69	0,049
0,30	51,88	0,055
0,32	52,06	0,060
0,34	52,25	0,065
0,36	52,44	0,069
0,38	52,64	0,072
0,40	52,83	0,076
0,42	53,02	0,078
0,44	53,22	0,080
0,46	53,42	0,082
0,48	53,61	0,084
0,50	53,81	0,085
0,52	54,01	0,087
0,54	54,20	0,088
0,56	54,40	0,088
0,58	54,60	0,089
0,60	54,80	0,090
0,62	55,00	0,090
0,64	55,20	0,090
0,66	55,39	0,091
0,68	55,59	0,091
0,70	55,79	0,091
0,72	55,99	0,091
0,74	56,19	0,092
0,76	56,39	0,092
0,78	56,59	0,092
0,80	56,79	0,092
0,82	56,99	0,092
0,84	57,19	0,092
0,86	57,39	0,093
0,88	57,59	0,093
0,90	57,79	0,093
0,92	57,99	0,093
0,94	58,19	0,093
0,96	58,39	0,093
0,98	58,59	0,093
1,00	58,78	0,094
1,02	58,98	0,094
1,04	59,18	0,094
1,06	59,39	0,094
1,08	59,58	0,094
1,10	59,78	0,094
1,12	59,98	0,094
1,14	60,18	0,094
1,16	60,38	0,095
1,18	60,58	0,095
1,20	60,78	0,095
1,22	60,98	0,095
1,24	61,18	0,095
1,26	61,38	0,095
1,28	61,58	0,095
1,30	61,78	0,095
1,32	61,98	0,095
1,34	62,18	0,095
1,36	62,38	0,095
1,38	62,58	0,095
1,40	62,78	0,095
1,42	62,98	0,095
1,44	63,18	0,095
1,46	63,38	0,096
1,48	63,58	0,096
1,50	63,78	0,096
1,52	63,98	0,096
1,54	64,18	0,096
1,56	64,38	0,096
1,58	64,58	0,096
1,60	64,78	0,096
1,62	64,98	0,096
1,64	65,18	0,096
1,66	65,38	0,096
1,68	65,58	0,096
1,70	65,78	0,096
1,72	65,98	0,096
1,74	66,18	0,096
1,76	66,38	0,096
1,78	66,58	0,096
1,80	66,78	0,096
1,82	66,98	0,096
1,84	67,18	0,096
1,86	67,38	0,096
1,88	67,58	0,096
1,90	67,78	0,096
1,92	67,98	0,097
1,94	68,18	0,097
1,96	68,38	0,097
1,98	68,58	0,097
2,00	68,78	0,097
2,02	68,98	0,097
2,04	69,18	0,097
2,06	69,38	0,097
2,08	69,58	0,097
2,10	69,78	0,097
2,12	69,98	0,097
2,14	70,18	0,097
2,16	70,38	0,097
2,18	70,58	0,097
2,20	70,78	0,097
2,22	70,98	0,097
2,24	71,18	0,097
2,26	71,38	0,097
2,28	71,58	0,097
2,30	71,78	0,097
2,32	71,98	0,097
2,34	72,18	0,097
2,36	72,38	0,097
2,38	72,58	0,097
2,40	72,78	0,097
2,42	72,98	0,097
2,44	73,18	0,097
2,46	73,37	0,097
2,48	73,58	0,098
2,50	73,78	0,098
2,52	73,97	0,098
2,54	74,17	0,098
2,56	74,37	0,098
2,58	74,57	0,098
2,60	74,77	0,098
2,62	74,97	0,098
2,64	75,17	0,098
2,66	75,37	0,098
2,68	75,57	0,098
2,70	75,77	0,098
2,72	75,97	0,098
2,74	76,17	0,098
2,76	76,37	0,098
2,78	76,57	0,098
2,80	76,77	0,098
2,82	76,97	0,098
2,84	77,17	0,098
2,86	77,37	0,098
2,88	77,57	0,098
2,90	77,77	0,098
2,92	77,97	0,098
2,94	78,17	0,098
2,96	78,37	0,099
2,98	78,57	0,099
3,00	78,77	0,099
3,02	78,97	0,099
3,04	79,17	0,099
3,06	79,37	0,099
3,08	79,57	0,099
3,10	79,77	0,099
3,12	79,97	0,099
3,14	80,17	0,099
3,16	80,37	0,099
3,18	80,57	0,099
3,20	80,77	0,099
3,22	80,97	0,099
3,24	81,17	0,099
3,26	81,37	0,099
3,28	81,57	0,099
3,30	81,77	0,099
3,32	81,97	0,099
3,34	82,17	0,099
3,36	82,37	0,099
3,38	82,57	0,099
3,40	82,77	0,100
3,42	82,97	0,100
3,44	83,17	0,100
3,46	83,37	0,100
3,48	83,57	0,100
3,50	83,77	0,100
3,52	83,97	0,100
3,54	84,17	0,100
3,56	84,37	0,100
3,58	84,57	0,100
3,60	84,77	0,100
3,62	84,97	0,100
3,64	85,17	0,100
3,66	85,37	0,100
3,68	85,57	0,100
3,70	85,77	0,100
3,72	85,97	0,101
3,74	86,17	0,101
3,76	86,37	0,101
3,78	86,57	0,101
3,80	86,77	0,101
3,82	86,97	0,101
3,84	87,17	0,101
3,86	87,37	0,101
3,88	87,57	0,101
3,90	87,77	0,101
3,92	87,97	0,101
3,94	88,17	0,101
3,96	88,37	0,101
3,98	88,58	0,101
4,00	88,78	0,101
4,02	88,98	0,101
4,04	89,18	0,101
4,06	89,38	0,102
4,08	89,58	0,102
4,10	89,78	0,102
4,12	89,98	0,102
4,14	90,18	0,102
4,16	90,38	0,102
4,18	90,58	0,102
4,20	90,78	0,102
4,22	90,98	0,102
4,24	91,18	0,102
4,26	91,38	0,102
4,28	91,58	0,102
4,30	91,78	0,102
4,32	91,98	0,102
4,34	92,18	0,102
4,36	92,38	0,102
4,38	92,58	0,102
4,40	92,78	0,102
4,42	92,98	0,103
4,44	93,18	0,103
4,46	93,38	0,103
4,48	93,58	0,103
4,50	93,78	0,103
4,52	93,98	0,103
4,54	94,18	0,103
4,56	94,38	0,103
4,58	94,58	0,103
4,60	94,78	0,103
4,62	94,98	0,103
4,64	95,18	0,103
4,66	95,38	0,103
4,68	95,58	0,103
4,70	95,78	0,103
4,72	95,98	0,103
4,74	96,18	0,104
4,76	96,38	0,104
4,78	96,58	0,104
4,80	96,78	0,104
4,82	96,98	0,104
4,84	97,18	0,104
4,86	97,38	0,104
4,88	97,58	0,104
4,90	97,78	0,104
4,92	97,99	0,104
4,94	98,18	0,104
4,96	98,38	0,104
4,98	98,58	0,104
5,00	98,79	0,104
5,02	98,98	0,104
5,04	99,18	0,104
5,06	99,39	0,104
5,08	99,58	0,105
5,10	99,79	0,105
5,12	99,99	0,105
5,14	100,19	0,105
5,16	100,39	0,105
5,18	100,59	0,105
5,20	100,79	0,105
5,22	100,99	0,105
5,24	101,19	0,105
5,26	101,39	0,105
5,28	101,59	0,105
5,30	101,79	0,105
5,32	101,99	0,105
5,34	102,19	0,105
5,36	102,39	0,105
5,38	102,59	0,105
5,40	102,79	0,105
5,42	102,99	0,106
5,44	103,19	0,106
5,46	103,39	0,106
5,48	103,59	0,106
5,50	103,79	0,106
5,52	103,99	0,106
5,54	104,19	0,106
5,56	104,39	0,106
5,58	104,59	0,106
5,60	104,79	0,106
5,62	104,99	0,106
5,64	105,19	0,106
5,66	105,39	0,106
5,68	105,59	0,106
5,70	105,79	0,106
5,72	105,99	0,106
5,74	106,19	0,107
5,76	106,39	0,107
5,78	106,59	0,107
5,80	106,79	0,107
5,82	106,99	0,107
5,84	107,19	0,107
5,86	107,39	0,107
5,88	107,59	0,107
5,90	107,79	0,107
5,92	107,99	0,107
5,94	108,19	0,107
5,96	108,39	0,107
5,98	108,59	0,107
6,00	108,79	0,107
6,02	108,99	0,107
6,04	109,19	0,107
6,06	109,39	0,107
6,08	109,59	0,107
6,10	109,79	0,108
6,12	109,99	0,108
6,14	110,19	0,108
6,16	110,39	0,108
6,18	110,59	0,108
6,20	110,79	0,108
6,22	110,99	0,108
6,24	111,19	0,108
6,26	111,39	0,108
6,28	111,59	0,108
6,30	111,79	0,108
6,32	111,99	0,108
6,34	112,19	0,108
6,36	112,39	0,108
6,38	112,59	0,108
6,40	112,79	0,108
6,42	112,99	0,108
6,44	113,19	0,108
6,46	113,39	0,109
6,48	113,59	0,109
6,50	113,79	0,109
6,52	114,00	0,109
6,54	114,20	0,109
6,56	114,40	0,109
6,58	114,59	0,109
6,60	114,79	0,109
6,62	115,00	0,109
6,64	115,19	0,109
6,66	115,39	0,109
6,68	115,59	0,109
6,70	115,79	0,109
6,72	116,00	0,109
6,74	116,20	0,109
6,76	116,40	0,110
6,78	116,60	0,110
6,80	116,80	0,110
6,82	117,00	0,110
6,84	117,20	0,110
6,86	117,40	0,110
6,88	117,60	0,110
6,90	117,80	0,110
6,92	118,00	0,110
6,94	118,20	0,110
6,96	118,40	0,110
6,98	118,60	0,110
7,00	118,80	0,110
7,02	119,00	0,110
7,04	119,20	0,110
7,06	119,40	0,110
7,08	119,60	0,111
7,10	119,80	0,111
7,12	120,00	0,111
7,14	120,20	0,111
7,16	120,40	0,111
7,18	120,60	0,111
7,20	120,80	0,111
7,22	121,00	0,111
7,24	121,20	0,111
7,26	121,40	0,111
7,28	121,60	0,111
7,30	121,80	0,111
7,32	122,00	0,111
7,34	122,20	0,111
7,36	122,40	0,111
7,38	122,60	0,111
7,40	122,80	0,112
7,42	123,00	0,112
7,44	123,20	0,112
7,46	123,40	0,112
7,48	123,60	0,112
7,50	123,80	0,112
7,52	124,00	0,112
7,54	124,20	0,112
7,56	124,40	0,112
7,58	124,60	0,112
7,60	124,80	0,112
7,62	125,00	0,112
7,64	125,20	0,112
7,66	125,40	0,112
7,68	125,60	0,113
7,70	125,80	0,113
7,72	126,00	0,113
7,74	126,20	0,113
7,76	126,40	0,113
7,78	126,60	0,113
7,80	126,80	0,113
7,82	127,00	0,113
7,84	127,20	0,113
7,86	127,40	0,113
7,88	127,60	0,113
7,90	127,80	0,113
7,92	128,00	0,113
7,94	128,20	0,113
7,96	128,40	0,113
7,98	128,60	0,113
8,00	128,80	0,114
8,02	129,00	0,114
8,04	129,20	0,114
8,06	129,40	0,114
8,08	129,60	0,114
8,10	129,80	0,114
8,12	130,00	0,114
8,14	130,20	0,114
8,16	130,40	0,114
8,18	130,60	0,114
8,20	130,80	0,114
8,22	131,00	0,114
8,24	131,20	0,114
8,26	131,40	0,114
8,28	131,60	0,114
8,30	131,80	0,115
8,32	132,00	0,115
8,34	132,20	0,115
8,36	132,41	0,115
8,38	132,60	0,115
8,40	132,80	0,115
8,42	133,00	0,115
8,44	133,21	0,115
8,46	133,41	0,115
8,48	133,61	0,115
8,50	133,80	0,115
8,52	134,01	0,115
8,54	134,21	0,115
8,56	134,41	0,115
8,58	134,61	0,115
8,60	134,80	0,115
8,62	135,01	0,116
8,64	135,21	0,116
8,66	135,41	0,116
8,68	135,61	0,116
8,70	135,81	0,116
8,72	136,01	0,116
8,74	136,21	0,116
8,76	136,41	0,116
8,78	136,61	0,116
8,80	136,81	0,116
8,82	137,01	0,116
8,84	137,21	0,116
8,86	137,41	0,116
8,88	137,61	0,116
8,90	137,81	0,116
8,92	138,01	0,117
8,94	138,21	0,117
8,96	138,41	0,117
8,98	138,61	0,117
9,00	138,81	0,117
9,02	139,01	0,117
9,04	139,21	0,117
9,06	139,41	0,117
9,08	139,61	0,117
9,10	139,81	0,117
9,12	140,01	0,117
9,14	140,21	0,117
9,16	140,41	0,117
9,18	140,61	0,117
9,20	140,81	0,117
9,22	141,01	0,118
9,24	141,21	0,118
9,26	141,41	0,118
9,28	141,61	0,118
9,30	141,81	0,118
9,32	142,01	0,118
9,34	142,21	0,118
9,36	142,41	0,118
9,38	142,61	0,118
9,40	142,81	0,118
9,42	143,01	0,118
9,44	143,21	0,118
9,46	143,41	0,118
9,48	143,61	0,118
9,50	143,81	0,118
9,52	144,01	0,119
9,54	144,21	0,119
9,56	144,41	0,119
9,58	144,61	0,119
9,60	144,81	0,119
9,62	145,01	0,119
9,64	145,21	0,119
9,66	145,41	0,119
9,68	145,61	0,119
9,70	145,81	0,119
9,72	146,01	0,119
9,74	146,21	0,119
9,76	146,41	0,119
9,78	146,61	0,119
9,80	146,81	0,119
9,82	147,01	0,119
9,84	147,21	0,119
9,86	147,41	0,119
9,88	147,61	0,120
9,90	147,81	0,120
9,92	148,01	0,120
9,94	148,21	0,120
9,96	148,41	0,120
9,98	148,61	0,120
10,00	148,81	0,120
10,02	149,01	0,120
10,04	149,21	0,120
10,06	149,41	0,120
10,08	149,61	0,120
10,10	149,81	0,120
10,12	150,01	0,120
10,14	150,21	0,120
10,16	150,41	0,120
10,18	150,61	0,120
10,20	150,81	0,121
10,22	151,01	0,121
10,24	151,21	0,121
10,26	151,41	0,121
10,28	151,61	0,121
10,30	151,81	0,121
10,32	152,01	0,121
10,34	152,21	0,121
10,36	152,41	0,121
10,38	152,61	0,121
10,40	152,81	0,121
10,42	153,01	0,121
10,44	153,21	0,121
10,46	153,41	0,121
10,48	153,61	0,121
10,50	153,81	0,121
10,52	154,01	0,122
10,54	154,21	0,122
10,56	154,41	0,122
10,58	154,61	0,122
10,60	154,81	0,122
10,62	155,01	0,122
10,64	155,21	0,122
10,66	155,41	0,122
10,68	155,62	0,122
10,70	155,81	0,122
10,72	156,01	0,122
10,74	156,21	0,122
10,76	156,41	0,122
10,78	156,61	0,122
10,80	156,81	0,122
10,82	157,01	0,122
10,84	157,21	0,123
10,86	157,41	0,123
10,88	157,61	0,123
10,90	157,81	0,123
10,92	158,01	0,123
10,94	158,21	0,123
10,96	158,41	0,123
10,98	158,61	0,123
11,00	158,82	0,123
11,02	159,02	0,123
11,04	159,21	0,123
11,06	159,41	0,123
11,08	159,62	0,123
11,10	159,81	0,123
11,12	160,01	0,123
11,14	160,21	0,124
11,16	160,42	0,124
11,18	160,62	0,124
11,20	160,82	0,124
11,22	161,02	0,124
11,24	161,22	0,124
11,26	161,42	0,124
11,28	161,62	0,124
11,30	161,82	0,124
11,32	162,02	0,124
11,34	162,21	0,124
11,36	162,42	0,124
11,38	162,62	0,124
11,40	162,82	0,124
11,42	163,02	0,124
11,44	163,22	0,125
11,46	163,42	0,125
11,48	163,62	0,125
11,50	163,82	0,125
11,52	164,02	0,125
11,54	164,22	0,125
11,56	164,42	0,125
11,58	164,62	0,125
11,60	164,82	0,125
11,62	165,02	0,125
11,64	165,22	0,125
11,66	165,42	0,125
11,68	165,62	0,125
11,70	165,82	0,125
11,72	166,02	0,125
11,74	166,22	0,126
11,76	166,42	0,126
11,78	166,62	0,126
11,80	166,82	0,126
11,82	167,02	0,126
11,84	167,22	0,126
11,86	167,42	0,126
11,88	167,62	0,126
11,90	167,82	0,126
11,92	168,02	0,126
11,94	168,22	0,126
11,96	168,42	0,126
11,98	168,62	0,126
12,00	168,82	0,126
12,02	169,02	0,126
12,04	169,22	0,126
12,06	169,42	0,126
12,08	169,62	0,126
12,10	169,82	0,127
12,12	170,02	0,127
12,14	170,22	0,127
12,16	170,42	0,127
12,18	170,62	0,127
12,20	170,82	0,127
12,22	171,02	0,127
12,24	171,22	0,127
12,26	171,42	0,127
12,28	171,62	0,127
12,30	171,82	0,127
12,32	172,02	0,127
12,34	172,22	0,127
12,36	172,42	0,127
12,38	172,62	0,127
12,40	172,82	0,127
12,42	173,02	0,128
12,44	173,22	0,128
12,46	173,42	0,128
12,48	173,62	0,128
12,50	173,82	0,128
12,52	174,02	0,128
12,54	174,22	0,128
12,56	174,42	0,128
12,58	174,62	0,128
12,60	174,82	0,128
12,62	175,02	0,128
12,64	175,22	0,128
12,66	175,42	0,128
12,68	175,62	0,128
12,70	175,82	0,128
12,72	176,02	0,128
12,74	176,22	0,129
12,76	176,42	0,129
12,78	176,62	0,129
12,80	176,82	0,129
12,82	177,02	0,129
12,84	177,22	0,129
12,86	177,42	0,129
12,88	177,62	0,129
12,90	177,82	0,129
12,92	178,02	0,129
12,94	178,22	0,129
12,96	178,42	0,129
12,98	178,62	0,129
13,00	178,82	0,129
13,02	179,02	0,129
13,04	179,22	0,129
13,06	179,42	0,129
13,08	179,62	0,129
13,10	179,82	0,130
13,12	180,02	0,130
13,14	180,22	0,130
13,16	180,42	0,130
13,18	180,62	0,130
13,20	180,82	0,130
13,22	181,02	0,130
13,24	181,22	0,130
13,26	181,42	0,130
13,28	181,62	0,130
13,30	181,82	0,130
13,32	182,02	0,130
13,34	182,22	0,130
13,36	182,42	0,130
13,38	182,62	0,130
13,40	182,82	0,130
13,42	183,02	0,131
13,44	183,22	0,131
13,46	183,42	0,131
13,48	183,62	0,131
13,50	183,82	0,131
13,52	184,02	0,131
13,54	184,22	0,131
13,56	184,42	0,131
13,58	184,62	0,131
13,60	184,82	0,131
13,62	185,02	0,131
13,64	185,22	0,131
13,66	185,42	0,131
13,68	185,62	0,131
13,70	185,82	0,131
13,72	186,02	0,131
13,74	186,22	0,131
13,76	186,42	0,132
13,78	186,62	0,132
13,80	186,82	0,132
13,82	187,03	0,132
13,84	187,22	0,132
13,86	187,43	0,132
13,88	187,62	0,132
13,90	187,83	0,132
13,92	188,03	0,132
13,94	188,23	0,132
13,96	188,43	0,132
13,98	188,62	0,132
14,00	188,83	0,132
14,02	189,03	0,132
14,04	189,22	0,132
14,06	189,43	0,132
14,08	189,62	0,132
14,10	189,82	0,132
14,12	190,02	0,132
14,14	190,23	0,133
14,16	190,43	0,133
14,18	190,63	0,133
14,20	190,83	0,133
14,22	191,03	0,133
14,24	191,23	0,133
14,26	191,43	0,133
14,28	191,63	0,133
14,30	191,83	0,133
14,32	192,03	0,133
14,34	192,23	0,133
14,36	192,43	0,133
14,38	192,63	0,133
14,40	192,83	0,133
14,42	193,03	0,133
14,44	193,23	0,133
14,46	193,43	0,134
14,48	193,63	0,134
14,50	193,83	0,134
14,52	194,03	0,134
14,54	194,23	0,134
14,56	194,43	0,134
14,58	194,63	0,134
14,60	194,83	0,134
14,62	195,03	0,134
14,64	195,23	0,134
14,66	195,43	0,134
14,68	195,63	0,134
14,70	195,83	0,134
14,72	196,03	0,134
14,74	196,23	0,134
14,76	196,43	0,134
14,78	196,63	0,134
14,80	196,83	0,134
14,82	197,03	0,134
14,84	197,23	0,134
14,86	197,43	0,135
14,88	197,63	0,135
14,90	197,83	0,135
14,92	198,03	0,135
14,94	198,23	0,135
14,96	198,43	0,135
14,98	198,63	0,135
15,00	198,83	0,135
15,02	199,03	0,135
15,04	199,23	0,135
15,06	199,43	0,135
15,08	199,63	0,135
15,10	199,83	0,135
15,12	200,03	0,135
15,14	200,23	0,135
15,16	200,43	0,135
15,18	200,63	0,135
15,20	200,83	0,135
15,22	201,03	0,136
15,24	201,23	0,136
15,26	201,43	0,136
15,28	201,63	0,136
15,30	201,83	0,136
15,32	202,03	0,136
15,34	202,23	0,136
15,36	202,43	0,136
15,38	202,63	0,136
15,40	202,83	0,136
15,42	203,03	0,136
15,44	203,23	0,136
15,46	203,43	0,136
15,48	203,63	0,136
15,50	203,83	0,136
15,52	204,03	0,136
15,54	204,23	0,136
15,56	204,43	0,136
15,58	204,63	0,136
15,60	204,83	0,137
15,62	205,03	0,137
15,64	205,23	0,137
15,66	205,43	0,137
15,68	205,63	0,137
15,70	205,83	0,137
15,72	206,03	0,137
15,74	206,23	0,137
15,76	206,43	0,137
15,78	206,63	0,137
15,80	206,83	0,137
15,82	207,03	0,137
15,84	207,23	0,137
15,86	207,43	0,137
15,88	207,63	0,137
15,90	207,83	0,137
15,92	208,03	0,137
15,94	208,23	0,137
15,96	208,43	0,137
15,98	208,63	0,137
16,00	208,83	0,138
16,02	209,03	0,138
16,04	209,23	0,138
16,06	209,43	0,138
16,08	209,63	0,138
16,10	209,83	0,138
16,12	210,03	0,138
16,14	210,23	0,138
16,16	210,43	0,138
16,18	210,63	0,138
16,20	210,83	0,138
16,22	211,03	0,138
16,24	211,23	0,138
16,26	211,43	0,138
16,28	211,63	0,138
16,30	211,83	0,138
16,32	212,03	0,138
16,34	212,23	0,138
16,36	212,43	0,138
16,38	212,63	0,138
16,40	212,83	0,139
16,42	213,03	0,139
16,44	213,23	0,139
16,46	213,43	0,139
16,48	213,63	0,139
16,50	213,83	0,139
16,52	214,03	0,139
16,54	214,23	0,139
16,56	214,43	0,139
16,58	214,63	0,139
16,60	214,83	0,139
16,62	215,03	0,139
16,64	215,23	0,139
16,66	215,43	0,139
16,68	215,63	0,139
16,70	215,83	0,139
16,72	216,03	0,139
16,74	216,23	0,139
16,76	216,43	0,140
16,78	216,63	0,140
16,80	216,83	0,140
16,82	217,03	0,140
16,84	217,23	0,140
16,86	217,43	0,140
16,88	217,63	0,140
16,90	217,83	0,140
16,92	218,03	0,140
16,94	218,23	0,140
16,96	218,43	0,140
16,98	218,64	0,140
17,00	218,83	0,140
17,02	219,04	0,140
17,04	219,24	0,140
17,06	219,44	0,140
17,08	219,64	0,140
17,10	219,84	0,140
17,12	220,04	0,140
17,14	220,23	0,140
17,16	220,44	0,140
17,18	220,64	0,141
17,20	220,84	0,141
17,22	221,04	0,141
17,24	221,24	0,141
17,26	221,44	0,141
17,28	221,64	0,141
17,30	221,84	0,141
17,32	222,04	0,141
17,34	222,24	0,141
17,36	222,44	0,141
17,38	222,64	0,141
17,40	222,84	0,141
17,42	223,04	0,141
17,44	223,24	0,141
17,46	223,44	0,141
17,48	223,64	0,141
17,50	223,84	0,141
17,52	224,04	0,141
17,54	224,24	0,141
17,56	224,44	0,141
17,58	224,64	0,141
17,60	224,84	0,141
17,62	225,04	0,141
17,64	225,24	0,142
17,66	225,44	0,142
17,68	225,64	0,142
17,70	225,84	0,142
17,72	226,04	0,142
17,74	226,24	0,142
17,76	226,44	0,142
17,78	226,64	0,142
17,80	226,84	0,142
17,82	227,04	0,142
17,84	227,24	0,142
17,86	227,44	0,142
17,88	227,64	0,142
17,90	227,84	0,142
17,92	228,04	0,142
17,94	228,24	0,142
17,96	228,44	0,142
17,98	228,64	0,142
18,00	228,84	0,142
18,02	229,04	0,142
18,04	229,24	0,142
18,06	229,44	0,142
18,08	229,64	0,142
18,10	229,84	0,142
18,12	230,04	0,142
18,14	230,24	0,142
18,16	230,44	0,143
18,18	230,64	0,143
18,20	230,84	0,143
18,22	231,04	0,143
18,24	231,24	0,143
18,26	231,44	0,143
18,28	231,64	0,143
18,30	231,84	0,143
18,32	232,04	0,143
18,34	232,24	0,143
18,36	232,44	0,143
18,38	232,64	0,143
18,40	232,84	0,143
18,42	233,04	0,143
18,44	233,24	0,143
18,46	233,44	0,143
18,48	233,64	0,143
18,50	233,84	0,143
18,52	234,04	0,143
18,54	234,24	0,143
18,56	234,44	0,143
18,58	234,64	0,143
18,60	234,84	0,143
18,62	235,04	0,143
18,64	235,24	0,143
18,66	235,44	0,143
18,68	235,64	0,144
18,70	235,84	0,144
18,72	236,04	0,144
18,74	236,24	0,144
18,76	236,44	0,144
18,78	236,64	0,144
18,80	236,84	0,144
18,82	237,04	0,144
18,84	237,24	0,144
18,86	237,44	0,144
18,88	237,64	0,144
18,90	237,84	0,144
18,92	238,04	0,144
18,94	238,24	0,144
18,96	238,44	0,144
18,98	238,64	0,144
19,00	238,84	0,144
19,02	239,04	0,144
19,04	239,24	0,144
19,06	239,44	0,144
19,08	239,64	0,145
19,10	239,84	0,145
19,12	240,04	0,145
19,14	240,24	0,145
19,16	240,44	0,145
19,18	240,64	0,145
19,20	240,84	0,145
19,22	241,04	0,145
19,24	241,24	0,145
19,26	241,44	0,145
19,28	241,64	0,145
19,30	241,84	0,145
19,32	242,04	0,145
19,34	242,24	0,145
19,36	242,44	0,145
19,38	242,64	0,145
19,40	242,84	0,145
19,42	243,04	0,145
19,44	243,24	0,145
19,46	243,44	0,145
19,48	243,64	0,145
19,50	243,84	0,145
19,52	244,04	0,145
19,54	244,24	0,145
19,56	244,44	0,145
19,58	244,64	0,145
19,60	244,84	0,146
19,62	245,04	0,146
19,64	245,24	0,146
19,66	245,44	0,146
19,68	245,64	0,146
19,70	245,84	0,146
19,72	246,04	0,146
19,74	246,24	0,146
19,76	246,44	0,146
19,78	246,64	0,146
19,80	246,84	0,146
19,82	247,04	0,146
19,84	247,24	0,146
19,86	247,44	0,146
19,88	247,64	0,146
19,90	247,84	0,146
19,92	248,04	0,146
19,94	248,24	0,146
19,96	248,44	0,146
19,98	248,64	0,146
20,00	248,84	0,146
20,02	249,04	0,146
20,04	249,24	0,146
20,06	249,44	0,146
20,08	249,64	0,146
20,10	249,84	0,146
20,12	250,04	0,146
20,14	250,24	0,146
20,16	250,44	0,146
20,18	250,64	0,146
20,20	250,84	0,146
20,22	251,04	0,147
20,24	251,24	0,147
20,26	251,44	0,147
20,28	251,64	0,147
20,30	251,84	0,147
20,32	252,05	0,147
20,34	252,25	0,147
20,36	252,45	0,147
20,38	252,65	0,147
20,40	252,85	0,147
20,42	253,05	0,147
20,44	253,24	0,147
20,46	253,45	0,147
20,48	253,65	0,147
20,50	253,84	0,147
20,52	254,04	0,147
20,54	254,25	0,147
20,56	254,45	0,147
20,58	254,65	0,147
20,60	254,85	0,147
20,62	255,05	0,147
20,64	255,25	0,147
20,66	255,45	0,147
20,68	255,65	0,147
20,70	255,85	0,147
20,72	256,05	0,148
20,74	256,25	0,148
20,76	256,45	0,148
20,78	256,65	0,148
20,80	256,85	0,148
20,82	257,05	0,148
20,84	257,25	0,148
20,86	257,45	0,148
20,88	257,65	0,148
20,90	257,85	0,148
20,92	258,05	0,148
20,94	258,25	0,148
20,96	258,45	0,148
20,98	258,65	0,148
21,00	258,85	0,148
21,02	259,05	0,148
21,04	259,25	0,148
21,06	259,45	0,148
21,08	259,65	0,148
21,10	259,85	0,148
21,12	260,05	0,148
21,14	260,25	0,148
21,16	260,45	0,148
21,18	260,65	0,148
21,20	260,85	0,148
21,22	261,05	0,148
21,24	261,25	0,148
21,26	261,45	0,148
21,28	261,65	0,148
21,30	261,85	0,148
21,32	262,05	0,148
21,34	262,25	0,148
21,36	262,45	0,148
21,38	262,65	0,148
21,40	262,85	0,148
21,42	263,05	0,148
21,44	263,25	0,148
21,46	263,45	0,148
21,48	263,65	0,148
21,50	263,85	0,148
21,52	264,05	0,148
21,54	264,25	0,148
21,56	264,45	0,148
21,58	264,65	0,148
21,60	264,85	0,148
21,62	265,05	0,148
21,64	265,25	0,148
21,66	265,45	0,148
21,68	265,65	0,148
21,70	265,85	0,148
21,72	266,05	0,148
21,74	266,25	0,148
21,76	266,45	0,148
21,78	266,65	0,148
21,80	266,85	0,148
21,82	267,05	0,148
21,84	267,25	0,148
21,86	267,45	0,148
21,88	267,65	0,148
21,90	267,85	0,148
21,92	268,05	0,149
21,94	268,25	0,149
21,96	268,45	0,148
21,98	268,65	0,149
22,00	268,85	0,148
22,02	269,05	0,148
22,04	269,25	0,148
22,06	269,45	0,148
22,08	269,65	0,148
22,10	269,85	0,148
22,12	270,05	0,148
22,14	270,25	0,148
22,16	270,45	0,148
22,18	270,65	0,148
22,20	270,85	0,148
22,22	271,05	0,149
22,24	271,25	0,149
22,26	271,45	0,149
22,28	271,65	0,149
22,30	271,85	0,149
22,32	272,05	0,149
22,34	272,25	0,149
22,36	272,45	0,149
22,38	272,65	0,149
22,40	272,85	0,149
22,42	273,05	0,149
22,44	273,25	0,149
22,46	273,45	0,149
22,48	273,65	0,149
22,50	273,85	0,149
22,52	274,05	0,149
22,54	274,25	0,149
22,56	274,45	0,149
22,58	274,65	0,149
22,60	274,85	0,149
22,62	275,05	0,149
22,64	275,25	0,149
22,66	275,45	0,149
22,68	275,65	0,149
22,70	275,85	0,149
22,72	276,05	0,149
22,74	276,25	0,149
22,76	276,45	0,149
22,78	276,65	0,149
22,80	276,85	0,150
22,82	277,05	0,150
22,84	277,25	0,150
22,86	277,45	0,150
22,88	277,65	0,150
22,90	277,85	0,150
22,92	278,05	0,150
22,94	278,25	0,150
22,96	278,45	0,150
22,98	278,65	0,150
23,00	278,85	0,150
23,02	279,05	0,150
23,04	279,25	0,150
23,06	279,46	0,150
23,08	279,65	0,150
23,10	279,85	0,150
23,12	280,05	0,150
23,14	280,25	0,150
23,16	280,45	0,150
23,18	280,66	0,150
23,20	280,85	0,150
23,22	281,05	0,150
23,24	281,25	0,150
23,26	281,45	0,150
23,28	281,65	0,150
23,30	281,85	0,150
23,32	282,06	0,150
23,34	282,25	0,150
23,36	282,46	0,150
23,38	282,66	0,150
23,40	282,86	0,150
23,42	283,05	0,150
23,44	283,26	0,150
23,46	283,46	0,150
23,48	283,66	0,150
23,50	283,85	0,150
23,52	284,06	0,150
23,54	284,26	0,150
23,56	284,45	0,150
23,58	284,66	0,150
23,60	284,86	0,150
23,62	285,06	0,150
23,64	285,26	0,150
23,66	285,46	0,150
23,68	285,66	0,150
23,70	285,86	0,150
23,72	286,06	0,150
23,74	286,26	0,150
23,76	286,46	0,150
23,78	286,66	0,150
23,80	286,86	0,150
23,82	287,06	0,150
23,84	287,26	0,150
23,86	287,46	0,150
23,88	287,66	0,150
23,90	287,86	0,150
23,92	288,06	0,150
23,94	288,26	0,150
23,96	288,46	0,151
23,98	288,66	0,151
24,00	288,86	0,151
24,02	289,06	0,151
24,04	289,26	0,151
24,06	289,46	0,151
24,08	289,66	0,151
24,10	289,86	0,151
24,12	290,06	0,151
24,14	290,26	0,151
24,16	290,46	0,151
24,18	290,66	0,151
24,20	290,86	0,151
24,22	291,06	0,151
24,24	291,26	0,151
24,26	291,46	0,151
24,28	291,66	0,151
24,30	291,86	0,151
24,32	292,06	0,151
24,34	292,26	0,151
24,36	292,46	0,151
24,38	292,66	0,151
24,40	292,86	0,151
24,42	293,06	0,151
24,44	293,26	0,151
24,46	293,46	0,151
24,48	293,66	0,151
24,50	293,86	0,151
24,52	294,06	0,151
24,54	294,26	0,151
24,56	294,46	0,151
24,58	294,66	0,151
24,60	294,86	0,151
24,62	295,06	0,151
24,64	295,26	0,151
24,66	295,46	0,151
24,68	295,66	0,151
24,70	295,86	0,151
24,72	296,06	0,151
24,74	296,26	0,151
24,76	296,46	0,151
24,78	296,66	0,151
24,80	296,86	0,151
24,82	297,06	0,151
24,84	297,26	0,151
24,86	297,46	0,151
24,88	297,66	0,151
24,90	297,86	0,151
24,92	298,06	0,151
24,94	298,26	0,151
24,96	298,46	0,151
24,98	298,66	0,151
25,00	298,86	0,151
25,02	299,06	0,151
25,04	299,26	0,151
25,06	299,46	0,151
25,08	299,66	0,152
25,10	299,86	0,152
25,12	300,06	0,152
25,14	300,26	0,152
25,16	300,46	0,152
25,18	300,66	0,152
25,20	300,86	0,152
25,22	301,06	0,152
25,24	301,26	0,152
25,26	301,46	0,152
25,28	301,66	0,152
25,30	301,86	0,152
25,32	302,06	0,152
25,34	302,26	0,152
25,36	302,46	0,152
25,38	302,66	0,152
25,40	302,86	0,152
25,42	303,06	0,152
25,44	303,26	0,152
25,46	303,46	0,152
25,48	303,66	0,152
25,50	303,86	0,152
25,52	304,06	0,152
25,54	304,26	0,152
25,56	304,46	0,152
25,58	304,66	0,152
25,60	304,86	0,152
25,62	305,06	0,152
25,64	305,26	0,152
25,66	305,46	0,152
25,68	305,66	0,152
25,70	305,86	0,153
25,72	306,06	0,153
25,74	306,26	0,153
25,76	306,46	0,153
25,78	306,66	0,153
25,80	306,86	0,153
25,82	307,06	0,153
25,84	307,26	0,153
25,86	307,46	0,153
25,88	307,66	0,153
25,90	307,86	0,153
25,92	308,06	0,153
25,94	308,26	0,153
25,96	308,46	0,153
25,98	308,66	0,153
26,00	308,86	0,153
26,02	309,06	0,153
26,04	309,26	0,153
26,06	309,46	0,153
26,08	309,66	0,153
26,10	309,86	0,153
26,12	310,06	0,154
26,14	310,26	0,154
26,16	310,46	0,154
26,18	310,66	0,154
26,20	310,86	0,154
26,22	311,06	0,154
26,24	311,26	0,154
26,26	311,46	0,154
26,28	311,66	0,154
26,30	311,86	0,154
26,32	312,06	0,154
26,34	312,26	0,154
26,36	312,46	0,154
26,38	312,66	0,154
26,40	312,86	0,154
26,42	313,06	0,154
26,44	313,26	0,154
26,46	313,46	0,155
26,48	313,66	0,155
26,50	313,86	0,155
26,52	314,06	0,155
26,54	314,26	0,155
26,56	314,46	0,155
26,58	314,66	0,155
26,60	314,86	0,155
26,62	315,06	0,155
26,64	315,26	0,155
26,66	315,46	0,155
26,68	315,66	0,155
26,70	315,86	0,155
26,72	316,06	0,155
26,74	316,26	0,155
26,76	316,46	0,155
26,78	316,66	0,155
26,80	316,86	0,156
26,82	317,06	0,156
26,84	317,26	0,156
26,86	317,46	0,156
26,88	317,66	0,156
26,90	317,86	0,156
26,92	318,06	0,156
26,94	318,26	0,156
26,96	318,46	0,156
26,98	318,66	0,156
27,00	318,86	0,156
27,02	319,06	0,157
27,04	319,26	0,157
27,06	319,46	0,157
27,08	319,66	0,157
27,10	319,86	0,157
27,12	320,06	0,157
27,14	320,26	0,157
27,16	320,46	0,157
27,18	320,66	0,158
27,20	320,86	0,158
27,22	321,06	0,158
27,24	321,26	0,158
27,26	321,46	0,158
27,28	321,66	0,158
27,30	321,86	0,158
27,32	322,06	0,158
27,34	322,26	0,159
27,36	322,46	0,159
27,38	322,66	0,159
27,40	322,86	0,159
27,42	323,06	0,159
27,44	323,26	0,159
27,46	323,46	0,159
27,48	323,66	0,160
27,50	323,86	0,160
27,52	324,06	0,160
27,54	324,26	0,160
27,56	324,46	0,160
27,58	324,66	0,160
27,60	324,86	0,161
27,62	325,06	0,161
27,64	325,26	0,161
27,66	325,46	0,161
27,68	325,66	0,161
27,70	325,86	0,161
27,72	326,06	0,162
27,74	326,26	0,162
27,76	326,46	0,162
27,78	326,66	0,162
27,80	326,86	0,162
27,82	327,06	0,163
27,84	327,26	0,163
27,86	327,46	0,163
27,88	327,66	0,163
27,90	327,86	0,163
27,92	328,06	0,163
27,94	328,26	0,164
27,96	328,46	0,164
27,98	328,66	0,164
28,00	328,86	0,164
28,02	329,06	0,164
28,04	329,26	0,164
28,06	329,46	0,165
28,08	329,66	0,165
28,10	329,86	0,165
28,12	330,06	0,165
28,14	330,26	0,165
28,16	330,46	0,165
28,18	330,66	0,166
28,20	330,86	0,166
28,22	331,06	0,166
28,24	331,26	0,166
28,26	331,46	0,166
28,28	331,66	0,166
28,30	331,86	0,167
28,32	332,06	0,167
28,34	332,26	0,167
28,36	332,46	0,167
28,38	332,66	0,167
28,40	332,86	0,168
28,42	333,06	0,168
28,44	333,26	0,168
28,46	333,46	0,168
28,48	333,66	0,168
28,50	333,86	0,169
28,52	334,06	0,169
28,54	334,26	0,169
28,56	334,46	0,169
28,58	334,66	0,170
28,60	334,86	0,170
28,62	335,06	0,170
28,64	335,26	0,171
28,66	335,46	0,171
28,68	335,66	0,171
28,70	335,86	0,171
28,72	336,06	0,172
28,74	336,26	0,172
28,76	336,46	0,173
28,78	336,65	0,173
28,80	336,86	0,173
28,82	337,06	0,174
28,84	337,26	0,174
28,86	337,45	0,175
28,88	337,65	0,175
28,90	337,86	0,176
28,92	338,05	0,176
28,94	338,25	0,177
28,96	338,45	0,177
28,98	338,65	0,178
29,00	338,85	0,178
29,02	339,05	0,179
29,04	339,25	0,180
29,06	339,45	0,180
29,08	339,65	0,181
29,10	339,85	0,181
29,12	340,05	0,182
29,14	340,25	0,182
29,16	340,45	0,183
29,18	340,65	0,184
29,20	340,85	0,184
29,22	341,05	0,185
29,24	341,25	0,186
29,26	341,45	0,187
29,28	341,65	0,187
29,30	341,85	0,188
29,32	342,05	0,189
29,34	342,25	0,189
29,36	342,45	0,190
29,38	342,65	0,190
29,40	342,85	0,191
29,42	343,05	0,191
29,44	343,25	0,192
29,46	343,45	0,192
29,48	343,65	0,193
29,50	343,85	0,194
29,52	344,05	0,194
29,54	344,25	0,195
29,56	344,45	0,195
29,58	344,65	0,196
29,60	344,85	0,197
29,62	345,05	0,197
29,64	345,25	0,198
29,66	345,45	0,199
29,68	345,65	0,199
29,70	345,85	0,200
29,72	346,05	0,200
29,74	346,25	0,201
29,76	346,44	0,201
29,78	346,65	0,202
29,80	346,85	0,202
29,82	347,05	0,202
29,84	347,24	0,203
29,86	347,44	0,203
29,88	347,64	0,204
29,90	347,84	0,204
29,92	348,04	0,204
29,94	348,24	0,205
29,96	348,44	0,205
29,98	348,64	0,205
29,99	348,76	0,205

[step]
Ramp 10.00 °C/min to 100.000 °C
Time	Temperature	Heat Flow (Normalized)
min	°C	W/g
29,99	348,78	0,205
30,01	348,94	0,206
30,03	349,10	0,206
30,04	349,23	0,206
30,06	349,31	0,196
30,08	349,36	0,178
30,09	349,36	0,154
30,11	349,33	0,125
30,13	349,28	0,093
30,14	349,21	0,059
30,16	349,13	0,025
30,18	349,02	-0,009
30,19	348,91	-0,041
30,21	348,79	-0,073
30,23	348,67	-0,102
30,24	348,53	-0,128
30,26	348,39	-0,152
30,28	348,25	-0,174
30,29	348,10	-0,193
30,31	347,95	-0,211
30,33	347,79	-0,226
30,34	347,64	-0,240
30,36	347,48	-0,252
30,38	347,33	-0,262
30,39	347,17	-0,271
30,41	347,01	-0,279
30,43	346,85	-0,286
30,44	346,68	-0,292
30,46	346,52	-0,297
30,48	346,36	-0,302
30,49	346,20	-0,306
30,51	346,03	-0,309
30,53	345,87	-0,313
30,54	345,70	-0,315
30,56	345,54	-0,318
30,58	345,37	-0,320
30,59	345,21	-0,322
30,61	345,04	-0,323
30,63	344,88	-0,325
30,64	344,71	-0,326
30,66	344,55	-0,327
30,68	344,38	-0,328
30,69	344,22	-0,329
30,71	344,05	-0,330
30,73	343,89	-0,331
30,74	343,72	-0,332
30,76	343,56	-0,332
30,78	343,39	-0,333
30,79	343,23	-0,333
30,81	343,06	-0,334
30,83	342,89	-0,334
30,84	342,73	-0,335
30,86	342,56	-0,335
30,88	342,40	-0,335
30,89	342,23	-0,336
30,91	342,07	-0,336
30,93	341,90	-0,336
30,94	341,73	-0,337
30,96	341,57	-0,337
30,98	341,40	-0,337
30,99	341,24	-0,337
31,01	341,07	-0,338
31,03	340,90	-0,338
31,04	340,74	-0,338
31,06	340,57	-0,338
31,08	340,41	-0,338
31,09	340,24	-0,338
31,11	340,07	-0,339
31,13	339,91	-0,339
31,14	339,74	-0,339
31,16	339,58	-0,339
31,18	339,41	-0,339
31,19	339,24	-0,339
31,21	339,08	-0,340
31,23	338,91	-0,340
31,24	338,75	-0,340
31,26	338,58	-0,340
31,28	338,41	-0,340
31,29	338,25	-0,340
31,31	338,08	-0,341
31,33	337,91	-0,341
31,34	337,75	-0,341
31,36	337,58	-0,341
31,38	337,41	-0,341
31,39	337,25	-0,341
31,41	337,08	-0,341
31,43	336,92	-0,341
31,44	336,75	-0,341
31,46	336,58	-0,342
31,48	336,42	-0,342
31,49	336,25	-0,342
31,51	336,08	-0,342
31,53	335,92	-0,342
31,54	335,75	-0,342
31,56	335,59	-0,342
31,58	335,42	-0,342
31,59	335,25	-0,342
31,61	335,09	-0,342
31,63	334,92	-0,342
31,64	334,75	-0,342
31,66	334,59	-0,342
31,68	334,42	-0,342
31,69	334,25	-0,342
31,71	334,09	-0,342
31,73	333,92	-0,342
31,74	333,76	-0,342
31,76	333,59	-0,342
31,78	333,42	-0,342
31,79	333,25	-0,342
31,81	333,09	-0,342
31,83	332,92	-0,342
31,84	332,76	-0,342
31,86	332,59	-0,342
31,88	332,42	-0,342
31,89	332,26	-0,342
31,91	332,09	-0,342
31,93	331,92	-0,342
31,94	331,76	-0,342
31,96	331,59	-0,342
31,98	331,42	-0,342
31,99	331,26	-0,342
32,01	331,09	-0,342
32,03	330,92	-0,342
32,04	330,76	-0,342
32,06	330,59	-0,342
32,08	330,42	-0,342
32,09	330,26	-0,342
32,11	330,09	-0,342
32,13	329,92	-0,342
32,14	329,76	-0,342
32,16	329,59	-0,342
32,18	329,42	-0,342
32,19	329,26	-0,342
32,21	329,09	-0,342
32,23	328,93	-0,342
32,24	328,76	-0,342
32,26	328,59	-0,342
32,28	328,43	-0,342
32,29	328,26	-0,342
32,31	328,09	-0,342
32,33	327,93	-0,342
32,34	327,76	-0,342
32,36	327,59	-0,342
32,38	327,43	-0,342
32,39	327,26	-0,341
32,41	327,09	-0,341
32,43	326,93	-0,341
32,44	326,76	-0,341
32,46	326,60	-0,341
32,48	326,43	-0,341
32,49	326,26	-0,341
32,51	326,10	-0,341
32,53	325,93	-0,341
32,54	325,76	-0,341
32,56	325,60	-0,341
32,58	325,43	-0,341
32,59	325,26	-0,341
32,61	325,10	-0,341
32,63	324,93	-0,341
32,64	324,76	-0,341
32,66	324,60	-0,341
32,68	324,43	-0,341
32,69	324,26	-0,341
32,71	324,10	-0,340
32,73	323,93	-0,340
32,74	323,76	-0,340
32,76	323,60	-0,340
32,78	323,43	-0,340
32,79	323,26	-0,340
32,81	323,10	-0,340
32,83	322,93	-0,340
32,84	322,76	-0,340
32,86	322,60	-0,340
32,88	322,43	-0,340
32,89	322,27	-0,340
32,91	322,10	-0,340
32,93	321,93	-0,340
32,94	321,76	-0,340
32,96	321,60	-0,340
32,98	321,43	-0,340
32,99	321,27	-0,340
33,01	321,10	-0,340
33,03	320,93	-0,340
33,04	320,77	-0,339
33,06	320,60	-0,339
33,08	320,43	-0,339
33,09	320,27	-0,339
33,11	320,10	-0,339
33,13	319,93	-0,339
33,14	319,77	-0,339
33,16	319,60	-0,339
33,18	319,43	-0,339
33,19	319,27	-0,339
33,21	319,10	-0,339
33,23	318,93	-0,339
33,24	318,77	-0,339
33,26	318,60	-0,339
33,28	318,44	-0,339
33,29	318,27	-0,338
33,31	318,10	-0,338
33,33	317,94	-0,338
33,34	317,77	-0,338
33,36	317,60	-0,338
33,38	317,44	-0,338
33,39	317,27	-0,338
33,41	317,10	-0,338
33,43	316,94	-0,338
33,44	316,77	-0,338
33,46	316,60	-0,338
33,48	316,44	-0,338
33,49	316,27	-0,338
33,51	316,10	-0,338
33,53	315,94	-0,338
33,54	315,77	-0,338
33,56	315,60	-0,337
33,58	315,44	-0,337
33,59	315,27	-0,337
33,61	315,10	-0,337
33,63	314,94	-0,337
33,64	314,77	-0,337
33,66	314,60	-0,337
33,68	314,44	-0,337
33,69	314,27	-0,337
33,71	314,11	-0,337
33,73	313,94	-0,337
33,74	313,77	-0,337
33,76	313,60	-0,337
33,78	313,44	-0,337
33,79	313,27	-0,337
33,81	313,11	-0,337
33,83	312,94	-0,336
33,84	312,77	-0,336
33,86	312,61	-0,336
33,88	312,44	-0,336
33,89	312,27	-0,336
33,91	312,11	-0,336
33,93	311,94	-0,336
33,94	311,77	-0,336
33,96	311,61	-0,336
33,98	311,44	-0,336
33,99	311,28	-0,336
34,01	311,11	-0,336
34,03	310,94	-0,336
34,04	310,78	-0,336
34,06	310,61	-0,335
34,08	310,44	-0,335
34,09	310,28	-0,335
34,11	310,11	-0,335
34,13	309,94	-0,335
34,14	309,78	-0,335
34,16	309,61	-0,335
34,18	309,44	-0,335
34,19	309,27	-0,335
34,21	309,11	-0,335
34,23	308,94	-0,335
34,24	308,78	-0,335
34,26	308,61	-0,335
34,28	308,44	-0,335
34,29	308,28	-0,335
34,31	308,11	-0,334
34,33	307,94	-0,334
34,34	307,78	-0,334
34,36	307,61	-0,334
34,38	307,44	-0,334
34,39	307,28	-0,334
34,41	307,11	-0,334
34,43	306,94	-0,334
34,44	306,78	-0,334
34,46	306,61	-0,334
34,48	306,44	-0,334
34,49	306,28	-0,333
34,51	306,11	-0,333
34,53	305,95	-0,333
34,54	305,78	-0,333
34,56	305,61	-0,333
34,58	305,45	-0,333
34,59	305,28	-0,333
34,61	305,11	-0,333
34,63	304,95	-0,333
34,64	304,78	-0,333
34,66	304,61	-0,333
34,68	304,45	-0,333
34,69	304,28	-0,332
34,71	304,11	-0,332
34,73	303,95	-0,332
34,74	303,78	-0,332
34,76	303,61	-0,332
34,78	303,45	-0,332
34,79	303,28	-0,332
34,81	303,11	-0,332
34,83	302,95	-0,332
34,84	302,78	-0,332
34,86	302,61	-0,332
34,88	302,45	-0,332
34,89	302,28	-0,331
34,91	302,11	-0,331
34,93	301,95	-0,331
34,94	301,78	-0,331
34,96	301,61	-0,331
34,98	301,45	-0,331
34,99	301,28	-0,331
35,01	301,12	-0,331
35,03	300,95	-0,331
35,04	300,78	-0,331
35,06	300,62	-0,331
35,08	300,45	-0,331
35,09	300,28	-0,330
35,11	300,12	-0,330
35,13	299,95	-0,330
35,14	299,78	-0,330
35,16	299,62	-0,330
35,18	299,45	-0,330
35,19	299,28	-0,330
35,21	299,12	-0,330
35,23	298,95	-0,330
35,24	298,78	-0,330
35,26	298,62	-0,329
35,28	298,45	-0,329
35,29	298,28	-0,329
35,31	298,12	-0,329
35,33	297,95	-0,329
35,34	297,79	-0,329
35,36	297,62	-0,329
35,38	297,45	-0,329
35,39	297,29	-0,329
35,41	297,12	-0,329
35,43	296,95	-0,329
35,44	296,79	-0,329
35,46	296,62	-0,328
35,48	296,45	-0,328
35,49	296,29	-0,328
35,51	296,12	-0,328
35,53	295,95	-0,328
35,54	295,79	-0,328
35,56	295,62	-0,328
35,58	295,45	-0,328
35,59	295,29	-0,328
35,61	295,12	-0,328
35,63	294,95	-0,328
35,64	294,79	-0,327
35,66	294,62	-0,327
35,68	294,45	-0,327
35,69	294,29	-0,327
35,71	294,12	-0,327
35,73	293,96	-0,327
35,74	293,79	-0,327
35,76	293,62	-0,327
35,78	293,46	-0,327
35,79	293,29	-0,327
35,81	293,12	-0,326
35,83	292,96	-0,326
35,84	292,79	-0,326
35,86	292,62	-0,326
35,88	292,46	-0,326
35,89	292,29	-0,326
35,91	292,12	-0,326
35,93	291,96	-0,326
35,94	291,79	-0,326
35,96	291,62	-0,326
35,98	291,46	-0,326
[...]
88,58	265,54	-0,311
88,59	265,37	-0,311
88,61	265,20	-0,311
88,63	265,04	-0,311
88,64	264,87	-0,311
88,66	264,70	-0,311
88,68	264,54	-0,311
88,69	264,37	-0,311
88,71	264,21	-0,311
88,73	264,04	-0,310
88,74	263,87	-0,310
88,76	263,70	-0,310
88,78	263,54	-0,310
88,79	263,37	-0,310
88,81	263,21	-0,310
88,83	263,04	-0,310
88,84	262,87	-0,310
88,86	262,71	-0,310
88,88	262,54	-0,310
88,89	262,37	-0,310
88,91	262,21	-0,310
88,93	262,04	-0,310
88,94	261,87	-0,310
88,96	261,71	-0,309
88,98	261,54	-0,309
88,99	261,37	-0,309
89,01	261,21	-0,309
89,03	261,04	-0,309
89,04	260,87	-0,309
89,06	260,71	-0,309
89,08	260,54	-0,309
89,09	260,37	-0,309
89,11	260,21	-0,309
89,13	260,04	-0,309
89,14	259,87	-0,309
89,16	259,71	-0,308
89,18	259,54	-0,308
89,19	259,38	-0,308
89,21	259,21	-0,308
89,23	259,04	-0,308
89,24	258,88	-0,308
89,26	258,71	-0,308
89,28	258,54	-0,308
89,29	258,38	-0,308
89,31	258,21	-0,308
89,33	258,04	-0,308
89,34	257,88	-0,308
89,36	257,71	-0,308
89,38	257,54	-0,308
89,39	257,38	-0,307
89,41	257,21	-0,307
89,43	257,04	-0,307
89,44	256,88	-0,307
89,46	256,71	-0,307
89,48	256,55	-0,307
89,49	256,38	-0,307
89,51	256,21	-0,307
89,53	256,05	-0,307
89,54	255,88	-0,307
89,56	255,71	-0,307
89,58	255,55	-0,307
89,59	255,38	-0,307
89,61	255,21	-0,307
89,63	255,05	-0,306
89,64	254,88	-0,306
89,66	254,71	-0,306
89,68	254,55	-0,306
89,69	254,38	-0,306
89,71	254,22	-0,306
89,73	254,05	-0,306
89,74	253,88	-0,306
89,76	253,72	-0,306
89,78	253,55	-0,306
89,79	253,38	-0,306
89,81	253,22	-0,306
89,83	253,05	-0,306
89,84	252,88	-0,306
89,86	252,72	-0,305
89,88	252,55	-0,305
89,89	252,38	-0,305
89,91	252,22	-0,305
89,93	252,05	-0,305
89,94	251,88	-0,305
89,96	251,72	-0,305
89,98	251,55	-0,305
89,99	251,38	-0,305
90,01	251,22	-0,305
90,03	251,05	-0,305
90,04	250,88	-0,305
90,06	250,72	-0,305
90,08	250,55	-0,304
90,09	250,38	-0,304
90,11	250,22	-0,304
90,13	250,05	-0,304
90,14	249,89	-0,304
90,16	249,72	-0,304
90,18	249,55	-0,304
90,19	249,39	-0,304
90,21	249,22	-0,304
90,23	249,05	-0,304
90,24	248,89	-0,304
90,26	248,72	-0,304
90,28	248,55	-0,304
90,29	248,39	-0,303
90,31	248,22	-0,303
90,33	248,05	-0,303
90,34	247,89	-0,303
90,36	247,72	-0,303
90,38	247,56	-0,303
90,39	247,39	-0,303
90,41	247,22	-0,303
90,43	247,06	-0,303
90,44	246,89	-0,303
90,46	246,72	-0,303
90,48	246,56	-0,303
90,49	246,39	-0,303
90,51	246,22	-0,303
90,53	246,06	-0,302
90,54	245,89	-0,302
90,56	245,72	-0,302
90,58	245,56	-0,302
90,59	245,39	-0,302
90,61	245,23	-0,302
90,63	245,06	-0,302
90,64	244,89	-0,302
90,66	244,73	-0,302
90,68	244,56	-0,302
90,69	244,39	-0,302
90,71	244,23	-0,302
90,73	244,06	-0,302
90,74	243,89	-0,302
90,76	243,73	-0,302
90,78	243,56	-0,301
90,79	243,39	-0,301
90,81	243,23	-0,301
90,83	243,06	-0,301
90,84	242,89	-0,301
90,86	242,73	-0,301
90,88	242,56	-0,301
90,89	242,40	-0,301
90,91	242,23	-0,301
90,93	242,06	-0,301
90,94	241,90	-0,301
90,96	241,73	-0,301
90,98	241,56	-0,301
90,99	241,40	-0,301
91,01	241,23	-0,301
91,03	241,06	-0,300
91,04	240,90	-0,300
91,06	240,73	-0,300
91,08	240,56	-0,300
91,09	240,40	-0,300
91,11	240,23	-0,300
91,13	240,06	-0,300
91,14	239,90	-0,300
91,16	239,73	-0,300
91,18	239,56	-0,300
91,19	239,40	-0,300
91,21	239,23	-0,300
91,23	239,07	-0,300
91,24	238,90	-0,300
91,26	238,73	-0,300
91,28	238,57	-0,300
91,29	238,40	-0,299
91,31	238,23	-0,299
91,33	238,07	-0,299
91,34	237,90	-0,299
91,36	237,73	-0,299
91,38	237,57	-0,299
91,39	237,40	-0,299
91,41	237,23	-0,299
91,43	237,07	-0,299
91,44	236,90	-0,299
91,46	236,74	-0,299
91,48	236,57	-0,299
91,49	236,40	-0,299
91,51	236,24	-0,299
91,53	236,07	-0,299
91,54	235,90	-0,298
91,56	235,74	-0,298
91,58	235,57	-0,298
91,59	235,40	-0,298
91,61	235,24	-0,298
91,63	235,07	-0,298
91,64	234,90	-0,298
91,66	234,74	-0,298
91,68	234,57	-0,298
91,69	234,41	-0,298
91,71	234,24	-0,298
91,73	234,07	-0,298
91,74	233,91	-0,298
91,76	233,74	-0,298
91,78	233,57	-0,297
91,79	233,41	-0,297
91,81	233,24	-0,297
91,83	233,07	-0,297
91,84	232,91	-0,297
91,86	232,74	-0,297
91,88	232,57	-0,297
91,89	232,41	-0,297
91,91	232,24	-0,297
91,93	232,07	-0,297
91,94	231,91	-0,297
91,96	231,74	-0,297
91,98	231,57	-0,297
91,99	231,41	-0,297
92,01	231,24	-0,296
92,03	231,08	-0,296
92,04	230,91	-0,296
92,06	230,74	-0,296
92,08	230,58	-0,296
92,09	230,41	-0,296
92,11	230,24	-0,296
92,13	230,08	-0,296
92,14	229,91	-0,296
92,16	229,74	-0,296
92,18	229,58	-0,296
92,19	229,41	-0,296
92,21	229,25	-0,296
92,23	229,08	-0,296
92,24	228,91	-0,296
92,26	228,75	-0,296
92,28	228,58	-0,296
92,29	228,41	-0,295
92,31	228,25	-0,295
92,33	228,08	-0,295
92,34	227,91	-0,295
92,36	227,75	-0,295
92,38	227,58	-0,295
92,39	227,41	-0,295
92,41	227,25	-0,295
92,43	227,08	-0,295
92,44	226,92	-0,295
92,46	226,75	-0,295
92,48	226,58	-0,295
92,49	226,42	-0,295
92,51	226,25	-0,295
92,53	226,08	-0,295
92,54	225,92	-0,294
92,56	225,75	-0,294
92,58	225,58	-0,294
92,59	225,42	-0,294
92,61	225,25	-0,294
92,63	225,08	-0,294
92,64	224,92	-0,294
92,66	224,75	-0,294
92,68	224,59	-0,294
92,69	224,42	-0,294
92,71	224,25	-0,294
92,73	224,09	-0,294
92,74	223,92	-0,294
92,76	223,75	-0,294
92,78	223,59	-0,294
92,79	223,42	-0,293
92,81	223,25	-0,293
92,83	223,09	-0,293
92,84	222,92	-0,293
92,86	222,76	-0,293
92,88	222,59	-0,293
92,89	222,42	-0,293
92,91	222,26	-0,293
92,93	222,09	-0,293
92,94	221,92	-0,293
92,96	221,76	-0,293
92,98	221,59	-0,293
92,99	221,42	-0,293
93,01	221,26	-0,293
93,03	221,09	-0,293
93,04	220,92	-0,293
93,06	220,76	-0,293
93,08	220,59	-0,293
93,09	220,42	-0,293
93,11	220,26	-0,293
93,13	220,09	-0,293
93,14	219,92	-0,292
93,16	219,76	-0,292
93,18	219,59	-0,292
93,19	219,42	-0,292
93,21	219,26	-0,292
93,23	219,09	-0,292
93,24	218,92	-0,292
93,26	218,76	-0,292
93,28	218,59	-0,292
93,29	218,42	-0,292
93,31	218,26	-0,292
93,33	218,09	-0,292
93,34	217,93	-0,292
93,36	217,76	-0,292
93,38	217,59	-0,292
93,39	217,43	-0,291
93,41	217,26	-0,291
93,43	217,09	-0,291
93,44	216,93	-0,291
93,46	216,76	-0,291
93,48	216,59	-0,291
93,49	216,43	-0,291
93,51	216,26	-0,291
93,53	216,09	-0,291
93,54	215,93	-0,291
93,56	215,76	-0,291
93,58	215,59	-0,291
93,59	215,43	-0,291
93,61	215,26	-0,291
93,63	215,09	-0,291
93,64	214,93	-0,291
93,66	214,76	-0,290
93,68	214,59	-0,290
93,69	214,43	-0,290
93,71	214,26	-0,290
93,73	214,09	-0,290
93,74	213,93	-0,290
93,76	213,76	-0,290
93,78	213,59	-0,290
93,79	213,43	-0,290
93,81	213,26	-0,290
93,83	213,09	-0,290
93,84	212,93	-0,290
93,86	212,76	-0,290
93,88	212,59	-0,290
93,89	212,43	-0,290
93,91	212,26	-0,290
93,93	212,09	-0,290
93,94	211,93	-0,289
93,96	211,76	-0,289
93,98	211,59	-0,289
93,99	211,43	-0,289
94,01	211,26	-0,289
94,03	211,09	-0,289
94,04	210,93	-0,289
94,06	210,76	-0,289
94,08	210,59	-0,289
94,09	210,43	-0,289
94,11	210,26	-0,289
94,13	210,09	-0,289
94,14	209,93	-0,289
94,16	209,76	-0,289
94,18	209,59	-0,289
94,19	209,43	-0,289
94,21	209,26	-0,289
94,23	209,09	-0,288
94,24	208,93	-0,288
94,26	208,76	-0,288
94,28	208,59	-0,288
94,29	208,43	-0,288
94,31	208,26	-0,288
94,33	208,09	-0,288
94,34	207,93	-0,288
94,36	207,76	-0,288
94,38	207,59	-0,288
94,39	207,43	-0,288
94,41	207,26	-0,288
94,43	207,09	-0,288
94,44	206,93	-0,288
94,46	206,76	-0,288
94,48	206,59	-0,288
94,49	206,43	-0,287
94,51	206,26	-0,287
94,53	206,09	-0,287
94,54	205,93	-0,287
94,56	205,76	-0,287
94,58	205,59	-0,287
94,59	205,43	-0,287
94,61	205,26	-0,287
94,63	205,09	-0,287
94,64	204,93	-0,287
94,66	204,76	-0,287
94,68	204,59	-0,287
94,69	204,43	-0,287
94,71	204,26	-0,287
94,73	204,09	-0,286
94,74	203,93	-0,286
94,76	203,76	-0,286
94,78	203,59	-0,286
94,79	203,43	-0,286
94,81	203,26	-0,286
94,83	203,09	-0,286
94,84	202,93	-0,286
94,86	202,76	-0,286
94,88	202,59	-0,286
94,89	202,43	-0,286
94,91	202,26	-0,286
94,93	202,09	-0,286
94,94	201,93	-0,286
94,96	201,76	-0,285
94,98	201,59	-0,285
94,99	201,43	-0,285
95,01	201,26	-0,285
95,03	201,09	-0,285
95,04	200,93	-0,285
95,06	200,76	-0,285
95,08	200,59	-0,285
95,09	200,43	-0,285
95,11	200,26	-0,285
95,13	200,10	-0,285
95,14	199,93	-0,285
95,16	199,76	-0,285
95,18	199,60	-0,285
95,19	199,43	-0,285
95,21	199,26	-0,284
95,23	199,10	-0,284
95,24	198,93	-0,284
95,26	198,76	-0,284
95,28	198,59	-0,284
95,29	198,43	-0,284
95,31	198,26	-0,284
95,33	198,10	-0,284
95,34	197,93	-0,284
95,36	197,76	-0,284
95,38	197,59	-0,284
95,39	197,43	-0,284
95,41	197,26	-0,284
95,43	197,10	-0,284
95,44	196,93	-0,284
95,46	196,76	-0,284
95,48	196,60	-0,283
95,49	196,43	-0,283
95,51	196,26	-0,283
95,53	196,10	-0,283
95,54	195,93	-0,283
95,56	195,76	-0,283
95,58	195,60	-0,283
95,59	195,43	-0,283
95,61	195,26	-0,283
95,63	195,10	-0,283
95,64	194,93	-0,283
95,66	194,76	-0,283
95,68	194,60	-0,283
95,69	194,43	-0,283
95,71	194,26	-0,283
95,73	194,10	-0,283
95,74	193,93	-0,282
95,76	193,76	-0,282
95,78	193,60	-0,282
95,79	193,43	-0,282
95,81	193,27	-0,282
95,83	193,10	-0,282
95,84	192,93	-0,282
95,86	192,77	-0,282
95,88	192,60	-0,282
95,89	192,43	-0,282
95,91	192,27	-0,282
95,93	192,10	-0,282
95,94	191,93	-0,282
95,96	191,76	-0,282
95,98	191,60	-0,282
95,99	191,43	-0,282
96,01	191,27	-0,282
96,03	191,10	-0,281
96,04	190,93	-0,281
96,06	190,77	-0,281
96,08	190,60	-0,281
96,09	190,43	-0,281
96,11	190,27	-0,281
96,13	190,10	-0,281
96,14	189,93	-0,281
96,16	189,77	-0,281
96,18	189,60	-0,281
96,19	189,43	-0,281
96,21	189,27	-0,281
96,23	189,10	-0,281
96,24	188,93	-0,281
96,26	188,77	-0,281
96,28	188,60	-0,281
96,29	188,43	-0,280
96,31	188,27	-0,280
96,33	188,10	-0,280
96,34	187,93	-0,280
96,36	187,77	-0,280
96,38	187,60	-0,280
96,39	187,43	-0,280
96,41	187,27	-0,280
96,43	187,10	-0,280
96,44	186,93	-0,280
96,46	186,77	-0,280
96,48	186,60	-0,280
96,49	186,43	-0,280
96,51	186,27	-0,280
96,53	186,10	-0,280
96,54	185,94	-0,280
96,56	185,77	-0,279
96,58	185,60	-0,279
96,59	185,44	-0,279
96,61	185,27	-0,279
96,63	185,10	-0,279
96,64	184,94	-0,279
96,66	184,77	-0,279
96,68	184,60	-0,279
96,69	184,44	-0,279
96,71	184,27	-0,279
96,73	184,10	-0,279
96,74	183,94	-0,279
96,76	183,77	-0,279
96,78	183,60	-0,279
96,79	183,44	-0,279
96,81	183,27	-0,279
96,83	183,10	-0,278
96,84	182,94	-0,278
96,86	182,77	-0,278
96,88	182,60	-0,278
96,89	182,44	-0,278
96,91	182,27	-0,278
96,93	182,10	-0,278
96,94	181,94	-0,278
96,96	181,77	-0,278
96,98	181,60	-0,278
96,99	181,44	-0,278
97,01	181,27	-0,278
97,03	181,10	-0,278
97,04	180,94	-0,278
97,06	180,77	-0,278
97,08	180,60	-0,277
97,09	180,44	-0,277
97,11	180,27	-0,277
97,13	180,10	-0,277
97,14	179,94	-0,277
97,16	179,77	-0,277
97,18	179,60	-0,277
97,19	179,44	-0,277
97,21	179,27	-0,277
97,23	179,11	-0,277
97,24	178,94	-0,277
97,26	178,77	-0,277
97,28	178,61	-0,277
97,29	178,44	-0,277
97,31	178,27	-0,277
97,33	178,11	-0,277
97,34	177,94	-0,276
97,36	177,77	-0,276
97,38	177,61	-0,276
97,39	177,44	-0,276
97,41	177,27	-0,276
97,43	177,11	-0,276
97,44	176,94	-0,276
97,46	176,77	-0,276
97,48	176,61	-0,276
97,49	176,44	-0,276
97,51	176,27	-0,276
97,53	176,11	-0,276
97,54	175,94	-0,276
97,56	175,77	-0,276
97,58	175,61	-0,276
97,59	175,44	-0,276
97,61	175,28	-0,276
97,63	175,11	-0,275
97,64	174,94	-0,275
97,66	174,78	-0,275
97,68	174,61	-0,275
97,69	174,44	-0,275
97,71	174,28	-0,275
97,73	174,11	-0,275
97,74	173,94	-0,275
97,76	173,78	-0,275
97,78	173,61	-0,275
97,79	173,44	-0,275
97,81	173,28	-0,275
97,83	173,11	-0,275
97,84	172,94	-0,275
97,86	172,78	-0,275
97,88	172,61	-0,275
97,89	172,44	-0,274
97,91	172,28	-0,274
97,93	172,11	-0,274
97,94	171,95	-0,274
97,96	171,78	-0,274
97,98	171,61	-0,274
97,99	171,44	-0,274
98,01	171,28	-0,274
98,03	171,11	-0,274
98,04	170,94	-0,274
98,06	170,78	-0,274
98,08	170,61	-0,274
98,09	170,45	-0,274
98,11	170,28	-0,274
98,13	170,11	-0,274
98,14	169,95	-0,274
98,16	169,78	-0,273
98,18	169,61	-0,273
98,19	169,45	-0,273
98,21	169,28	-0,273
98,23	169,11	-0,273
98,24	168,95	-0,273
98,26	168,78	-0,273
98,28	168,61	-0,273
98,29	168,45	-0,273
98,31	168,28	-0,273
98,33	168,11	-0,273
98,34	167,95	-0,273
98,36	167,78	-0,273
98,38	167,61	-0,273
98,39	167,45	-0,273
98,41	167,28	-0,272
98,43	167,11	-0,272
98,44	166,95	-0,272
98,46	166,78	-0,272
98,48	166,61	-0,272
98,49	166,45	-0,272
98,51	166,28	-0,272
98,53	166,12	-0,272
98,54	165,95	-0,272
98,56	165,78	-0,272
98,58	165,62	-0,272
98,59	165,45	-0,272
98,61	165,28	-0,272
98,63	165,12	-0,272
98,64	164,95	-0,272
98,66	164,78	-0,271
98,68	164,62	-0,271
98,69	164,45	-0,271
98,71	164,28	-0,271
98,73	164,12	-0,271
98,74	163,95	-0,271
98,76	163,78	-0,271
98,78	163,62	-0,271
98,79	163,45	-0,271
98,81	163,29	-0,271
98,83	163,12	-0,271
98,84	162,95	-0,271
98,86	162,79	-0,271
98,88	162,62	-0,271
98,89	162,45	-0,271
98,91	162,29	-0,271
98,93	162,12	-0,270
98,94	161,95	-0,270
98,96	161,78	-0,270
98,98	161,62	-0,270
98,99	161,45	-0,270
99,01	161,29	-0,270
99,03	161,12	-0,270
99,04	160,95	-0,270
99,06	160,79	-0,270
99,08	160,62	-0,270
99,09	160,45	-0,270
99,11	160,29	-0,270
99,13	160,12	-0,270
99,14	159,95	-0,270
99,16	159,79	-0,270
99,18	159,62	-0,270
99,19	159,45	-0,269
99,21	159,29	-0,269
99,23	159,12	-0,269
99,24	158,95	-0,269
99,26	158,79	-0,269
99,28	158,62	-0,269
99,29	158,45	-0,269
99,31	158,29	-0,269
99,33	158,12	-0,269
99,34	157,95	-0,269
99,36	157,79	-0,269
99,38	157,62	-0,269
99,39	157,46	-0,269
99,41	157,29	-0,269
99,43	157,12	-0,268
99,44	156,95	-0,268
99,46	156,79	-0,268
99,48	156,62	-0,268
99,49	156,45	-0,268
99,51	156,29	-0,268
99,53	156,12	-0,268
99,54	155,96	-0,268
99,56	155,79	-0,268
99,58	155,62	-0,268
99,59	155,46	-0,268
99,61	155,29	-0,268
99,63	155,12	-0,268
99,64	154,96	-0,268
99,66	154,79	-0,267
99,68	154,62	-0,267
99,69	154,46	-0,267
99,71	154,29	-0,267
99,73	154,12	-0,267
99,74	153,96	-0,267
99,76	153,79	-0,267
99,78	153,62	-0,267
99,79	153,46	-0,267
99,81	153,29	-0,267
99,83	153,12	-0,267
99,84	152,96	-0,267
99,86	152,79	-0,267
99,88	152,62	-0,266
99,89	152,46	-0,266
99,91	152,29	-0,266
99,93	152,12	-0,266
99,94	151,96	-0,266
99,96	151,79	-0,266
99,98	151,63	-0,266
99,99	151,46	-0,266
100,01	151,29	-0,266
100,03	151,13	-0,266
100,04	150,96	-0,266
100,06	150,79	-0,266
100,08	150,63	-0,266
100,09	150,46	-0,266
100,11	150,29	-0,266
100,13	150,13	-0,265
100,14	149,96	-0,265
100,16	149,79	-0,265
100,18	149,63	-0,265
100,19	149,46	-0,265
100,21	149,29	-0,265
100,23	149,13	-0,265
100,24	148,96	-0,265
100,26	148,79	-0,265
100,28	148,63	-0,265
100,29	148,46	-0,265
100,31	148,29	-0,265
100,33	148,13	-0,265
100,34	147,96	-0,265
100,36	147,80	-0,265
100,38	147,63	-0,264
100,39	147,46	-0,264
100,41	147,30	-0,264
100,43	147,13	-0,264
100,44	146,96	-0,264
100,46	146,80	-0,264
100,48	146,63	-0,264
100,49	146,46	-0,264
100,51	146,30	-0,264
100,53	146,13	-0,264
100,54	145,96	-0,264
100,56	145,80	-0,264
100,58	145,63	-0,264
100,59	145,46	-0,264
100,61	145,30	-0,264
100,63	145,13	-0,264
100,64	144,96	-0,263
100,66	144,80	-0,263
100,68	144,63	-0,263
100,69	144,46	-0,263
100,71	144,30	-0,263
100,73	144,13	-0,263
100,74	143,96	-0,263
100,76	143,80	-0,263
100,78	143,63	-0,263
100,79	143,47	-0,263
100,81	143,30	-0,263
100,83	143,13	-0,263
100,84	142,97	-0,263
100,86	142,80	-0,263
100,88	142,63	-0,263
100,89	142,46	-0,263
100,91	142,30	-0,262
100,93	142,13	-0,262
100,94	141,97	-0,262
100,96	141,80	-0,262
100,98	141,63	-0,262
100,99	141,47	-0,262
101,01	141,30	-0,262
101,03	141,13	-0,262
101,04	140,97	-0,262
101,06	140,80	-0,262
101,08	140,63	-0,262
101,09	140,47	-0,262
101,11	140,30	-0,262
101,13	140,13	-0,262
101,14	139,97	-0,262
101,16	139,80	-0,262
101,18	139,64	-0,261
101,19	139,47	-0,261
101,21	139,30	-0,261
101,23	139,14	-0,261
101,24	138,97	-0,261
101,26	138,80	-0,261
101,28	138,64	-0,261
101,29	138,47	-0,261
101,31	138,30	-0,261
101,33	138,14	-0,261
101,34	137,97	-0,261
101,36	137,80	-0,261
101,38	137,64	-0,261
101,39	137,47	-0,261
101,41	137,30	-0,261
101,43	137,14	-0,260
101,44	136,97	-0,260
101,46	136,80	-0,260
101,48	136,64	-0,260
101,49	136,47	-0,260
101,51	136,30	-0,260
101,53	136,14	-0,260
101,54	135,97	-0,260
101,56	135,81	-0,260
101,58	135,64	-0,260
101,59	135,47	-0,260
101,61	135,31	-0,260
101,63	135,14	-0,260
101,64	134,97	-0,260
101,66	134,81	-0,260
101,68	134,64	-0,259
101,69	134,47	-0,259
101,71	134,31	-0,259
101,73	134,14	-0,259
101,74	133,97	-0,259
101,76	133,81	-0,259
101,78	133,64	-0,259
101,79	133,47	-0,259
101,81	133,31	-0,259
101,83	133,14	-0,259
101,84	132,97	-0,259
101,86	132,81	-0,259
101,88	132,64	-0,259
101,89	132,47	-0,259
101,91	132,31	-0,259
101,93	132,14	-0,258
101,94	131,98	-0,258
101,96	131,81	-0,258
101,98	131,64	-0,258
101,99	131,48	-0,258
102,01	131,31	-0,258
102,03	131,14	-0,258
102,04	130,98	-0,258
102,06	130,81	-0,258
102,08	130,64	-0,258
102,09	130,48	-0,258
102,11	130,31	-0,258
102,13	130,14	-0,258
102,14	129,98	-0,258
102,16	129,81	-0,258
102,18	129,64	-0,257
102,19	129,48	-0,257
102,21	129,31	-0,257
102,23	129,14	-0,257
102,24	128,98	-0,257
102,26	128,81	-0,257
102,28	128,64	-0,257
102,29	128,48	-0,257
102,31	128,31	-0,257
102,33	128,15	-0,257
102,34	127,98	-0,257
102,36	127,81	-0,257
102,38	127,65	-0,257
102,39	127,48	-0,257
102,41	127,31	-0,257
102,43	127,15	-0,257
102,44	126,98	-0,256
102,46	126,81	-0,256
102,48	126,65	-0,256
102,49	126,48	-0,256
102,51	126,31	-0,256
102,53	126,15	-0,256
102,54	125,98	-0,256
102,56	125,81	-0,256
102,58	125,65	-0,256
102,59	125,48	-0,256
102,61	125,31	-0,256
102,63	125,15	-0,256
102,64	124,98	-0,256
102,66	124,81	-0,256
102,68	124,65	-0,256
102,69	124,48	-0,256
102,71	124,32	-0,255
102,73	124,15	-0,255
102,74	123,98	-0,255
102,76	123,82	-0,255
102,78	123,65	-0,255
102,79	123,48	-0,255
102,81	123,32	-0,255
102,83	123,15	-0,255
102,84	122,98	-0,255
102,86	122,82	-0,255
102,88	122,65	-0,255
102,89	122,48	-0,255
102,91	122,32	-0,255
102,93	122,15	-0,255
102,94	121,98	-0,255
102,96	121,82	-0,254
102,98	121,65	-0,254
102,99	121,48	-0,254
103,01	121,32	-0,254
103,03	121,15	-0,254
103,04	120,98	-0,254
103,06	120,82	-0,254
103,08	120,65	-0,254
103,09	120,49	-0,254
103,11	120,32	-0,254
103,13	120,15	-0,254
103,14	119,99	-0,254
103,16	119,82	-0,254
103,18	119,65	-0,254
103,19	119,49	-0,254
103,21	119,32	-0,254
103,23	119,15	-0,253
103,24	118,99	-0,253
103,26	118,82	-0,253
103,28	118,65	-0,253
103,29	118,49	-0,253
103,31	118,32	-0,253
103,33	118,15	-0,253
103,34	117,99	-0,253
103,36	117,82	-0,253
103,38	117,65	-0,253
103,39	117,49	-0,253
103,41	117,32	-0,253
103,43	117,16	-0,253
103,44	116,99	-0,253
103,46	116,82	-0,253
103,48	116,65	-0,252
103,49	116,49	-0,252
103,51	116,32	-0,252
103,53	116,16	-0,252
103,54	115,99	-0,252
103,56	115,82	-0,252
103,58	115,66	-0,252
103,59	115,49	-0,252
103,61	115,32	-0,252
103,63	115,16	-0,252
103,64	114,99	-0,252
103,66	114,82	-0,252
103,68	114,66	-0,252
103,69	114,49	-0,252
103,71	114,32	-0,252
103,73	114,16	-0,252
103,74	113,99	-0,251
103,76	113,83	-0,251
103,78	113,66	-0,251
103,79	113,49	-0,251
103,81	113,33	-0,251
103,83	113,16	-0,251
103,84	112,99	-0,251
103,86	112,83	-0,251
103,88	112,66	-0,251
103,89	112,49	-0,251
103,91	112,33	-0,251
103,93	112,16	-0,251
103,94	111,99	-0,251
103,96	111,83	-0,251
103,98	111,66	-0,251
103,99	111,49	-0,250
104,01	111,33	-0,250
104,03	111,16	-0,250
104,04	110,99	-0,250
104,06	110,83	-0,250
104,08	110,66	-0,250
104,09	110,50	-0,250
104,11	110,33	-0,250
104,13	110,16	-0,250
104,14	109,99	-0,250
104,16	109,83	-0,250
104,18	109,66	-0,250
104,19	109,50	-0,250
104,21	109,33	-0,250
104,23	109,16	-0,250
104,24	109,00	-0,249
104,26	108,83	-0,249
104,28	108,66	-0,249
104,29	108,50	-0,249
104,31	108,33	-0,249
104,33	108,16	-0,249
104,34	108,00	-0,249
104,36	107,83	-0,249
104,38	107,67	-0,249
104,39	107,50	-0,249
104,41	107,33	-0,249
104,43	107,17	-0,249
104,44	107,00	-0,249
104,46	106,83	-0,249
104,48	106,67	-0,249
104,49	106,50	-0,249
104,51	106,33	-0,248
104,53	106,17	-0,248
104,54	106,00	-0,248
104,56	105,83	-0,248
104,58	105,67	-0,248
104,59	105,50	-0,248
104,61	105,34	-0,248
104,63	105,17	-0,248
104,64	105,00	-0,248
104,66	104,83	-0,248
104,68	104,67	-0,248
104,69	104,50	-0,248
104,71	104,34	-0,248
104,73	104,17	-0,248
104,74	104,00	-0,248
104,76	103,84	-0,247
104,78	103,67	-0,247
104,79	103,50	-0,247
104,81	103,34	-0,247
104,83	103,17	-0,247
104,84	103,00	-0,247
104,86	102,84	-0,247
104,88	102,67	-0,247
104,89	102,51	-0,247
104,91	102,34	-0,247
104,93	102,17	-0,247
104,94	102,01
104,96	101,84
104,98	101,67
104,99